test_author_can_update_comment (tests.CommentPermissionsTest.test_author_can_update_comment) ... ok
test_contributor_can_see_comment (tests.CommentPermissionsTest.test_contributor_can_see_comment) ... ok
test_contributor_cannot_update_comment (tests.CommentPermissionsTest.test_contributor_cannot_update_comment) ... ok
test_stranger_cannot_see_comment (tests.CommentPermissionsTest.test_stranger_cannot_see_comment) ... ERROR
test_author_can_update_issue (tests.IssuePermissionsTest.test_author_can_update_issue) ... ok
test_contributor_can_list_issues (tests.IssuePermissionsTest.test_contributor_can_list_issues) ... ok
test_contributor_can_view_specific_issue (tests.IssuePermissionsTest.test_contributor_can_view_specific_issue) ... ok
test_author_can_update_project (tests.ProjectPermissionsTest.test_author_can_update_project) ... ok
test_contributor_can_view_project (tests.ProjectPermissionsTest.test_contributor_can_view_project) ... ok
test_contributor_cannot_update_project (tests.ProjectPermissionsTest.test_contributor_cannot_update_project) ... ok
test_stranger_cannot_view_project (tests.ProjectPermissionsTest.test_stranger_cannot_view_project) ... FAIL
test_cannot_create_user_with_age_under_15 (tests.UserCreationTest.test_cannot_create_user_with_age_under_15) ... ok

======================================================================
ERROR: test_stranger_cannot_see_comment (tests.CommentPermissionsTest.test_stranger_cannot_see_comment)
----------------------------------------------------------------------
Traceback (most recent call last):
  File "C:\Users\andre\Desktop\RESTFUL\support_api\tests.py", line 72, in test_stranger_cannot_see_comment
    response = self.client.get(f'/api/comments/{self.comment.id}/', **self.stranger_auth_header)
                                                                      ^^^^^^^^^^^^^^^^^^^^^^^^^
AttributeError: 'CommentPermissionsTest' object has no attribute 'stranger_auth_header'

======================================================================
FAIL: test_stranger_cannot_view_project (tests.ProjectPermissionsTest.test_stranger_cannot_view_project)
----------------------------------------------------------------------
Traceback (most recent call last):
  File "C:\Users\andre\Desktop\RESTFUL\support_api\tests.py", line 184, in test_stranger_cannot_view_project
    self.assertEqual(response.status_code, 403)
    ~~~~~~~~~~~~~~~~^^^^^^^^^^^^^^^^^^^^^^^^^^^
AssertionError: 404 != 403

----------------------------------------------------------------------
Ran 12 tests in 26.919s

FAILED (failures=1, errors=1)


Rapport de couverture:
Name                                 Stmts   Miss  Cover
--------------------------------------------------------
rest\urls.py                             6      0   100%
support_api\migrations\__init__.py       0      0   100%
support_api\permissions.py              54      8    85%
support_api\serializers.py              60      7    88%
support_api\tests.py                   146      2    99%
support_api\urls.py                     10      0   100%
support_api\views.py                    79     20    75%
--------------------------------------------------------
TOTAL                                  355     37    90%
